Workbook

Sheet Legend
A1: Algo toolbox: decision-making algorithms for engineering projects
A2: Item | B2: Meaning
A3: Purpose | B3: One place for the thinking and quality algorithms every project uses: Six Sigma (DMAIC), statistics, and computational thinking, cross-walked to each other. This is the decision algorithm the projects improve over time.
A4: How to use | B4: Start at Crosswalk. Pick the DMAIC phase you are in, read the tool's formula and decision rule, then the computational-thinking method and statistics method it relies on. Use Decision Algorithms to pick a test or control chart. Log every failure on Failure Log and read Failure Pareto.
A5: Source of truth | B5: toolbox_data.py. Edit there and run build_toolbox.py; never hand-edit this workbook.
A6: Source status | B6: baseline = written from the standard method, book page cite pending extraction. extracted = taken from the owner's book with page cite. See Sources.
A7: Improvement rule | B7: A change to this toolbox counts as improvement only when a metric on Failure Pareto (count per category per project) drops beyond its noise.
A9: Color | B9: Meaning
A10: Define | B10: DMAIC Define phase (band color, light rows below it)
A11: Measure | B11: DMAIC Measure phase (band color, light rows below it)
A12: Analyze | B12: DMAIC Analyze phase (band color, light rows below it)
A13: Improve | B13: DMAIC Improve phase (band color, light rows below it)
A14: Control | B14: DMAIC Control phase (band color, light rows below it)
... A18: Failure log and Pareto | B18: Failure log and Pareto sheet header and rows

Sheet Crosswalk
A1: Crosswalk: Six Sigma (DMAIC) x computational thinking x statistics
A2: Six Sigma tool | B2: Algorithm / formula | C2: Decision rule | D2: Computational thinking method | E2: Statistics method
A3: DEFINE
A4: Project charter | B4: Problem = what, where, when, how big (baseline metric). Goal = metric, baseline, target, date. | C4: Charter approved when the goal is a measurable metric with baseline and target. | D4: Abstraction Termination and stop conditions | E4: -
A5: SIPOC | B5: Map 5 to 7 high-level steps; list inputs and outputs per step. | C5: Scope fixed when start and end points are named. | D5: Decomposition Abstraction | E5: -
A6: VOC to CTQ tree | B6: Need -> driver -> CTQ (metric + spec limits LSL/USL). | C6: Each leaf has an operational definition and spec limits. | D6: Decomposition Recursion Abstraction | E6: -
A7: Kano model | B7: Paired functional / dysfunctional survey questions -> Kano category table. | C7: Basic needs are met first; performance needs are optimized. | D7: Pattern recognition Sorting and prioritization | E7: Descriptive statistics (IPS ch. 1-2)
A8: Cost of poor quality (COPQ) | B8: COPQ = defect rate x cost per defect x annual volume (+ appraisal + prevention). | C8: Project proceeds when COPQ exceeds project cost. | D8: Complexity and trade-offs | E8: -
A9: MEASURE
A10: Operational definitions | B10: Metric = what is measured + method + instrument + unit + pass/fail criterion. | C10: Two people measuring the same unit get the same answer. | D10: Abstraction Data representation | E10: -
A11: Data collection plan and sample size | B11: Mean: n = (z* sigma / E)^2. Proportion: n = z*^2 p(1-p) / E^2. Round up. | C11: n meets the margin of error E at the chosen confidence. | D11: Algorithm design Data representation | E11: Sampling distributions and CLT (IPS ch. 3, 5) Power and sample size (IPS ch. 6)
A12: Gage R&R (MSA, ANOVA method) | B12: %GRR = sigma_GRR / sigma_total x 100. %GRR to tolerance = 6 sigma_GRR / (USL - LSL) x 100. ndc = 1.41 x sigma_part / sigma_GRR, truncated to an integer. | C12: %GRR < 10% accept; 10 to 30% conditional; > 30% reject (AIAG). ndc >= 5. | D12: Evaluation Testing and verification | E12: Two-way ANOVA (IPS ch. 13)
A13: Attribute agreement analysis | B13: Cohen's kappa = (p_o - p_e) / (1 - p_e); Fleiss' kappa for 3+ appraisers. | C13: kappa >= 0.75 good; 0.40 to 0.75 marginal; < 0.40 poor. AIAG: effectiveness >= 90%, miss rate <= 2%, false alarm <= 5%. A chi-square test shows association, not agreement. | D13: Evaluation | E13: -
A14: Normality check | B14: Normal probability plot; Anderson-Darling or Shapiro-Wilk test. | C14: p > alpha means no evidence against normality; decide from the plot. Large n: rely on the plot. Small n: the test has little power. | D14: Pattern recognition Evaluation | E14: Normal distribution and z (IPS ch. 1)
A15: Baseline capability | B15: Cp = (USL - LSL) / 6 sigma_within. Cpk = min(USL - mean, mean - LSL) / 3 sigma_within. Pp, Ppk use overall sigma. sigma_within = Rbar/d2 (Xbar-R), sbar/c4 (Xbar-S), MRbar/1.128 (I-MR). | C15: Cpk >= 1.33 capable; 1.00 to 1.33 marginal; < 1.00 not capable. Six Sigma goal Cp 2.0, Cpk 1.5. PPAP new process: Ppk >= 1.67. Requires a stable process first. | D15: Evaluation Abstraction | E15: Process capability (IPS ch. 17 (companion)) Normal distribution and z (IPS ch. 1)
A16: DPMO and sigma level | B16: DPMO = defects / (units x opportunities) x 10^6. Sigma level = 1.5 - NORM.S.INV(DPMO/10^6). Short-term sigma level = 3 Cpk. | C16: The 1.5 shift is the long-term convention; state it when used. | D16: Abstraction | E16: Normal distribution and z (IPS ch. 1)
A17: ANALYZE
A18: Pareto analysis | B18: Count per category, sort descending, cumulative % = running sum / total. | C18: Work the categories that reach about 80% cumulative first. | D18: Sorting and prioritization Greedy strategy Pattern recognition | E18: Descriptive statistics (IPS ch. 1-2)
A19: Fishbone (Ishikawa) | B19: Branches: Man, Machine, Method, Material, Measurement, Mother Nature (6M). | C19: Every branch is examined before any cause is chosen. | D19: Decomposition Breadth-first search | E19: -
A20: 5 Whys | B20: Ask why until the answer is an actionable, controllable cause. | C20: Stop at a cause you can change and verify with data. | D20: Depth-first search Recursion Termination and stop conditions | E20: -
A21: FMEA | B21: RPN = Severity x Occurrence x Detection (each 1 to 10). AIAG-VDA 2019 uses Action Priority tables instead. | C21: Act on highest RPN (AIAG 4th) or High AP, review Medium AP (AIAG-VDA 2019). House rule, stricter than AIAG-VDA: any Severity 9 to 10 gets an action or a documented justification. | D21: Sorting and prioritization Decomposition Heuristics | E21: -
A22: Hypothesis testing | B22: H0 vs Ha; pick the test from the Decision Algorithms sheet; compute statistic and p-value. | C22: Reject H0 when p < alpha, after checking assumptions. Report the CI and effect size. | D22: Evaluation Decision trees Testing and verification | E22: One-sample t (CI and test) (IPS ch. 7) Two-sample t (Welch) (IPS ch. 7) Paired t (IPS ch. 7) Inference for proportions (IPS ch. 8) Chi-square test for two-way tables (IPS ch. 9) One-way ANOVA (IPS ch. 12) Nonparametric tests (IPS ch. 15 (companion)) Bootstrap and permutation tests (IPS ch. 16 (companion))
A23: Correlation and regression | B23: b1 = r sy / sx; b0 = ybar - b1 xbar; R^2; t = b1 / SE(b1). | C23: Slope significant at alpha and residuals show no pattern. | D23: Modeling and simulation Pattern recognition | E23: Simple linear regression inference (IPS ch. 10) Multiple regression (IPS ch. 11)
A24: Multi-vari chart | B24: Plot within-piece, piece-to-piece, and time-to-time variation together. | C24: Investigate the family with the largest spread first. | D24: Pattern recognition Decomposition | E24: Descriptive statistics (IPS ch. 1-2)
A25: Half-split / component search | B25: Test the midpoint; keep the failing half; repeat. Steps = ceil(log2 N). | C25: Stop when one component remains and swapping it moves the fault. | D25: Divide and conquer Binary search Debugging | E25: -
A26: IMPROVE
A27: Design of experiments (2^k factorial) | B27: Effect = mean(Y at +) - mean(Y at -); regression coefficient = effect / 2. Runs = 2^k (x replicates). ANOVA on effects. | C27: Keep factors whose effects are significant; confirm with a confirmation run. | D27: Modeling and simulation Optimization / search over a space Iteration Testing and verification | E27: Two-way ANOVA (IPS ch. 13) Multiple regression (IPS ch. 11)
A28: Response surface / steepest ascent | B28: Move along the gradient of the fitted first-order model; fit second order near the peak. | C28: Stop when response stops improving beyond noise. | D28: Optimization / search over a space Termination and stop conditions Iteration | E28: Multiple regression (IPS ch. 11)
A29: Pugh / solution selection matrix | B29: Score each option vs a datum on weighted criteria: + / S / -; sum weighted scores. | C29: Pick the highest weighted score; check for a hybrid. | D29: Sorting and prioritization Complexity and trade-offs | E29: -
A30: Pilot and before/after test | B30: Two-sample (Welch) t or paired t on before vs after; two-proportion z for rates. Power analysis sets n. | C30: Improvement real when p < alpha and the CI excludes zero in the right direction. | D30: Evaluation Testing and verification | E30: Two-sample t (Welch) (IPS ch. 7) Paired t (IPS ch. 7) Inference for proportions (IPS ch. 8) Power and sample size (IPS ch. 6)
A31: Poka-yoke (mistake proofing) | B31: Control (prevent) or warning (detect) device at the error source. | C31: Re-score FMEA Occurrence/Detection after install. | D31: Algorithm design State machines | E31: -
A32: CONTROL
A33: Control chart selection | B33: See Decision Algorithms sheet (I-MR, Xbar-R, Xbar-S, p, np, c, u). | C33: Chart follows data type and subgroup size. | D33: Decision trees Data representation | E33: Statistical process control (IPS ch. 17 (companion))
A34: Xbar-R and I-MR charts | B34: Xbar-R: UCL/LCL = Xbarbar +/- A2 Rbar; R: UCL = D4 Rbar, LCL = D3 Rbar. I-MR: xbar +/- 2.66 MRbar; MR: UCL = 3.267 MRbar, LCL = 0. | C34: Western Electric: 1 point beyond 3 sigma; 2 of 3 consecutive beyond 2 sigma on the same side; 4 of 5 consecutive beyond 1 sigma on the same side; 8 consecutive on one side of the center line. | D34: Pattern recognition Invariants | E34: Statistical process control (IPS ch. 17 (companion))
A35: p and c charts | B35: p: pbar +/- 3 sqrt(pbar(1 - pbar)/n). c: cbar +/- 3 sqrt(cbar). LCL floors at 0. | C35: Same Western Electric rules. | D35: Pattern recognition Invariants | E35: Statistical process control (IPS ch. 17 (companion)) Inference for proportions (IPS ch. 8)
A36: Control plan and reaction plan | B36: Row per CTQ: spec, method, sample size, frequency, owner, reaction steps. | C36: Every out-of-control signal has a written if-then reaction. | D36: State machines Algorithm design Generalization | E36: -
A37: Sustained capability and hand-off | B37: Recompute Cpk/Ppk on post-change data; compare to baseline. | C37: Close when Cpk >= target for the agreed period and the owner signs. | D37: Evaluation Generalization Memoization / caching | E37: Process capability (IPS ch. 17 (companion))

Sheet CT x DMAIC
A1: Matrix: how many Six Sigma tools in each phase use each thinking method
A2: Computational thinking method | B2: Define | C2: Measure | D2: Analyze | E2: Improve | F2: Control | G2: Total
A3: Decomposition | B3: 2 | D3: 3 | G3: =SUM(B3:F3)
A4: Pattern recognition | B4: 1 | C4: 1 | D4: 3 | F4: 2 | G4: =SUM(B4:F4)
A5: Abstraction | B5: 3 | C5: 3 | G5: =SUM(B5:F5)
A6: Algorithm design | C6: 1 | E6: 1 | F6: 1 | G6: =SUM(B6:F6)
A7: Evaluation | C7: 4 | D7: 1 | E7: 1 | F7: 1 | G7: =SUM(B7:F7)
A8: Generalization | F8: 2 | G8: =SUM(B8:F8)
A9: Iteration | E9: 2 | G9: =SUM(B9:F9)
A10: Recursion | B10: 1 | D10: 1 | G10: =SUM(B10:F10)
A11: Termination and stop conditions | B11: 1 | D11: 1 | E11: 1 | G11: =SUM(B11:F11)
A12: Invariants | F12: 2 | G12: =SUM(B12:F12)
A13: Divide and conquer | D13: 1 | G13: =SUM(B13:F13)
A14: Binary search | D14: 1 | G14: =SUM(B14:F14)
A15: Breadth-first search | D15: 1 | G15: =SUM(B15:F15)
A16: Depth-first search | D16: 1 | G16: =SUM(B16:F16)
A17: Sorting and prioritization | B17: 1 | D17: 2 | E17: 1 | G17: =SUM(B17:F17)
A18: Greedy strategy | D18: 1 | G18: =SUM(B18:F18)
A19: Heuristics | D19: 1 | G19: =SUM(B19:F19)
A20: Decision trees | D20: 1 | F20: 1 | G20: =SUM(B20:F20)
A21: Data representation | C21: 2 | F21: 1 | G21: =SUM(B21:F21)
A22: Modeling and simulation | D22: 1 | E22: 1 | G22: =SUM(B22:F22)
A23: Optimization / search over a space | E23: 2 | G23: =SUM(B23:F23)
A24: Debugging | D24: 1 | G24: =SUM(B24:F24)
A25: Testing and verification | C25: 1 | D25: 1 | E25: 2 | G25: =SUM(B25:F25)
A26: State machines | E26: 1 | F26: 1 | G26: =SUM(B26:F26)
A27: Complexity and trade-offs | B27: 1 | E27: 1 | G27: =SUM(B27:F27)
A28: Memoization / caching | F28: 1 | G28: =SUM(B28:F28)

Sheet Six Sigma
A1: Six Sigma (DMAIC) tools: Black Belt reference
A2: Tool | B2: Purpose | C2: Algorithm / formula | D2: Decision rule | E2: Output | F2: Source status
A3: DEFINE
A4: Project charter | B4: Fix the problem, goal, scope, and owner before work starts. | C4: Problem = what, where, when, how big (baseline metric). Goal = metric, baseline, target, date. | D4: Charter approved when the goal is a measurable metric with baseline and target. | E4: Signed charter | F4: baseline
A5: SIPOC | B5: Bound the process: Suppliers, Inputs, Process (5 to 7 steps), Outputs, Customers. | C5: Map 5 to 7 high-level steps; list inputs and outputs per step. | D5: Scope fixed when start and end points are named. | E5: SIPOC diagram | F5: baseline
A6: VOC to CTQ tree | B6: Turn customer needs into measurable Critical-to-Quality requirements. | C6: Need -> driver -> CTQ (metric + spec limits LSL/USL). | D6: Each leaf has an operational definition and spec limits. | E6: CTQ tree | F6: baseline
A7: Kano model | B7: Classify requirements as basic, performance, or delighter. | C7: Paired functional / dysfunctional survey questions -> Kano category table. | D7: Basic needs are met first; performance needs are optimized. | E7: Ranked requirement list | F7: baseline
A8: Cost of poor quality (COPQ) | B8: Size the prize in money. | C8: COPQ = defect rate x cost per defect x annual volume (+ appraisal + prevention). | D8: Project proceeds when COPQ exceeds project cost. | E8: COPQ estimate | F8: baseline
A9: MEASURE
A10: Operational definitions | B10: Make every metric measurable the same way by anyone. | C10: Metric = what is measured + method + instrument + unit + pass/fail criterion. | D10: Two people measuring the same unit get the same answer. | E10: Definition table | F10: baseline
A11: Data collection plan and sample size | B11: Collect enough of the right data. | C11: Mean: n = (z* sigma / E)^2. Proportion: n = z*^2 p(1-p) / E^2. Round up. | D11: n meets the margin of error E at the chosen confidence. | E11: Plan with n, frequency, owner | F11: baseline
A12: Gage R&R (MSA, ANOVA method) | B12: Prove the measurement system is good enough. | C12: %GRR = sigma_GRR / sigma_total x 100. %GRR to tolerance = 6 sigma_GRR / (USL - LSL) x 100. ndc = 1.41 x sigma_part / sigma_GRR, truncated to an integer. | D12: %GRR < 10% accept; 10 to 30% conditional; > 30% reject (AIAG). ndc >= 5. | E12: MSA report | F12: baseline
A13: Attribute agreement analysis | B13: Prove pass/fail judgments are consistent. | C13: Cohen's kappa = (p_o - p_e) / (1 - p_e); Fleiss' kappa for 3+ appraisers. | D13: kappa >= 0.75 good; 0.40 to 0.75 marginal; < 0.40 poor. AIAG: effectiveness >= 90%, miss rate <= 2%, false alarm <= 5%. A chi-square test shows association, not agreement. | E13: Agreement report | F13: baseline
A14: Normality check | B14: Decide whether normal-theory methods apply. | C14: Normal probability plot; Anderson-Darling or Shapiro-Wilk test. | D14: p > alpha means no evidence against normality; decide from the plot. Large n: rely on the plot. Small n: the test has little power. | E14: Plot + test result | F14: baseline
A15: Baseline capability | B15: Measure how well the process meets spec today. | C15: Cp = (USL - LSL) / 6 sigma_within. Cpk = min(USL - mean, mean - LSL) / 3 sigma_within. Pp, Ppk use overall sigma. sigma_within = Rbar/d2 (Xbar-R), sbar/c4 (Xbar-S), MRbar/1.128 (I-MR). | D15: Cpk >= 1.33 capable; 1.00 to 1.33 marginal; < 1.00 not capable. Six Sigma goal Cp 2.0, Cpk 1.5. PPAP new process: Ppk >= 1.67. Requires a stable process first. | E15: Capability report | F15: baseline
A16: DPMO and sigma level | B16: Express defect performance on one scale. | C16: DPMO = defects / (units x opportunities) x 10^6. Sigma level = 1.5 - NORM.S.INV(DPMO/10^6). Short-term sigma level = 3 Cpk. | D16: The 1.5 shift is the long-term convention; state it when used. | E16: Baseline sigma | F16: baseline
A17: ANALYZE
A18: Pareto analysis | B18: Find the vital few causes. | C18: Count per category, sort descending, cumulative % = running sum / total. | D18: Work the categories that reach about 80% cumulative first. | E18: Pareto chart | F18: baseline
A19: Fishbone (Ishikawa) | B19: List all candidate causes by category. | C19: Branches: Man, Machine, Method, Material, Measurement, Mother Nature (6M). | D19: Every branch is examined before any cause is chosen. | E19: Cause list | F19: baseline
A20: 5 Whys | B20: Drill one cause chain to its root. | C20: Ask why until the answer is an actionable, controllable cause. | D20: Stop at a cause you can change and verify with data. | E20: Root cause chain | F20: baseline
A21: FMEA | B21: Rank failure modes by risk. | C21: RPN = Severity x Occurrence x Detection (each 1 to 10). AIAG-VDA 2019 uses Action Priority tables instead. | D21: Act on highest RPN (AIAG 4th) or High AP, review Medium AP (AIAG-VDA 2019). House rule, stricter than AIAG-VDA: any Severity 9 to 10 gets an action or a documented justification. | E21: FMEA table | F21: baseline
A22: Hypothesis testing | B22: Prove a suspected cause with data. | C22: H0 vs Ha; pick the test from the Decision Algorithms sheet; compute statistic and p-value. | D22: Reject H0 when p < alpha, after checking assumptions. Report the CI and effect size. | E22: Verified causes | F22: baseline
A23: Correlation and regression | B23: Quantify how Y depends on X. | C23: b1 = r sy / sx; b0 = ybar - b1 xbar; R^2; t = b1 / SE(b1). | D23: Slope significant at alpha and residuals show no pattern. | E23: Y = f(X) model | F23: baseline
A24: Multi-vari chart | B24: See which family of variation dominates. | C24: Plot within-piece, piece-to-piece, and time-to-time variation together. | D24: Investigate the family with the largest spread first. | E24: Variation family | F24: baseline
A25: Half-split / component search | B25: Isolate the faulty stage or part fast. | C25: Test the midpoint; keep the failing half; repeat. Steps = ceil(log2 N). | D25: Stop when one component remains and swapping it moves the fault. | E25: Isolated cause | F25: baseline
A26: IMPROVE
A27: Design of experiments (2^k factorial) | B27: Find which factors move Y and by how much. | C27: Effect = mean(Y at +) - mean(Y at -); regression coefficient = effect / 2. Runs = 2^k (x replicates). ANOVA on effects. | D27: Keep factors whose effects are significant; confirm with a confirmation run. | E27: Optimal settings | F27: baseline
A28: Response surface / steepest ascent | B28: Climb to the optimum setting. | C28: Move along the gradient of the fitted first-order model; fit second order near the peak. | D28: Stop when response stops improving beyond noise. | E28: Optimum | F28: baseline
A29: Pugh / solution selection matrix | B29: Choose among solutions against criteria. | C29: Score each option vs a datum on weighted criteria: + / S / -; sum weighted scores. | D29: Pick the highest weighted score; check for a hybrid. | E29: Chosen solution | F29: baseline
A30: Pilot and before/after test | B30: Prove the fix works. | C30: Two-sample (Welch) t or paired t on before vs after; two-proportion z for rates. Power analysis sets n. | D30: Improvement real when p < alpha and the CI excludes zero in the right direction. | E30: Verified improvement | F30: baseline
A31: Poka-yoke (mistake proofing) | B31: Make the error impossible or instantly visible. | C31: Control (prevent) or warning (detect) device at the error source. | D31: Re-score FMEA Occurrence/Detection after install. | E31: Mistake-proof device | F31: baseline
A32: CONTROL
A33: Control chart selection | B33: Pick the right chart for the data. | C33: See Decision Algorithms sheet (I-MR, Xbar-R, Xbar-S, p, np, c, u). | D33: Chart follows data type and subgroup size. | E33: Chosen chart | F33: baseline
A34: Xbar-R and I-MR charts | B34: Detect when the process changes. | C34: Xbar-R: UCL/LCL = Xbarbar +/- A2 Rbar; R: UCL = D4 Rbar, LCL = D3 Rbar. I-MR: xbar +/- 2.66 MRbar; MR: UCL = 3.267 MRbar, LCL = 0. | D34: Western Electric: 1 point beyond 3 sigma; 2 of 3 consecutive beyond 2 sigma on the same side; 4 of 5 consecutive beyond 1 sigma on the same side; 8 consecutive on one side of the center line. | E34: Control chart | F34: baseline
A35: p and c charts | B35: Monitor defective rates and defect counts. | C35: p: pbar +/- 3 sqrt(pbar(1 - pbar)/n). c: cbar +/- 3 sqrt(cbar). LCL floors at 0. | D35: Same Western Electric rules. | E35: Attribute chart | F35: baseline
A36: Control plan and reaction plan | B36: Keep the gain: who checks what, how often, and what to do. | C36: Row per CTQ: spec, method, sample size, frequency, owner, reaction steps. | D36: Every out-of-control signal has a written if-then reaction. | E36: Control plan | F36: baseline
A37: Sustained capability and hand-off | B37: Prove the gain holds and transfer ownership. | C37: Recompute Cpk/Ppk on post-change data; compare to baseline. | D37: Close when Cpk >= target for the agreed period and the owner signs. | E37: Close-out report | F37: baseline

Sheet Computational Thinking
A1: Computational thinking methods and how they apply to Six Sigma
A2: ID | B2: Method | C2: Definition | D2: How it applies to Six Sigma | E2: DMAIC phases (from tags) | F2: Six Sigma tools that use it | G2: Source status
A3: CT-DEC | B3: Decomposition | C3: Break a problem into smaller parts that can be solved separately. | D3: SIPOC, CTQ tree, fishbone branches, and work breakdown all decompose a process or requirement. | E3: Define, Analyze | F3: SIPOC VOC to CTQ tree Fishbone (Ishikawa) FMEA Multi-vari chart | G3: baseline
A4: CT-PAT | B4: Pattern recognition | C4: Find similarities, trends, and regularities in data or problems. | D4: Control-chart run rules, Pareto, multi-vari, and stratification are pattern detectors over process data. | E4: Define, Measure, Analyze, Control | F4: Kano model Normality check Pareto analysis Correlation and regression Multi-vari chart Xbar-R and I-MR charts p and c charts | G4: baseline
A5: CT-ABS | B5: Abstraction | C5: Keep the details that matter; drop the rest. | D5: Operational definitions, CTQ metrics, and Y = f(X) reduce a process to measurable variables. | E5: Define, Measure | F5: Project charter SIPOC VOC to CTQ tree Operational definitions Baseline capability DPMO and sigma level | G5: baseline
A6: CT-ALG | B6: Algorithm design | C6: Write an exact, ordered, finite set of steps that solves the problem. | D6: DMAIC itself, standard work, data collection plans, and reaction plans are algorithms. | E6: Measure, Improve, Control | F6: Data collection plan and sample size Poka-yoke (mistake proofing) Control plan and reaction plan | G6: baseline
A7: CT-EVAL | B7: Evaluation | C7: Judge whether a solution is correct, efficient, and fit for purpose. | D7: Hypothesis tests, MSA, capability, and before/after tests evaluate claims with data. | E7: Measure, Analyze, Improve, Control | F7: Gage R&R (MSA, ANOVA method) Attribute agreement analysis Normality check Baseline capability Hypothesis testing Pilot and before/after test Sustained capability and hand-off | G7: baseline
A8: CT-GEN | B8: Generalization | C8: Adapt a solution so it solves a wider class of problems. | D8: Replicating a fix to sister processes; control plans as reusable templates. | E8: Control | F8: Control plan and reaction plan Sustained capability and hand-off | G8: baseline
A9: CT-ITER | B9: Iteration | C9: Repeat a step until a condition is met. | D9: PDCA cycles and sequential DOE rounds iterate toward the target. | E9: Improve | F9: Design of experiments (2^k factorial) Response surface / steepest ascent | G9: baseline
A10: CT-REC | B10: Recursion | C10: Solve a problem by solving smaller instances of itself, down to a base case. | D10: CTQ trees and 5 Whys recurse; the base case is a measurable CTQ or an actionable root cause. | E10: Define, Analyze | F10: VOC to CTQ tree 5 Whys | G10: baseline
A11: CT-STOP | B11: Termination and stop conditions | C11: Every loop has a condition that guarantees it ends. | D11: Charter goals, 5 Whys stopping rule, steepest-ascent stop, and agent term limits (attempts, time, tokens). | E11: Define, Analyze, Improve | F11: Project charter 5 Whys Response surface / steepest ascent | G11: baseline
A12: CT-INV | B12: Invariants | C12: A property that must stay true on every pass of a loop. | D12: Control limits express the invariant 'process is stable'; a signal means the invariant broke. | E12: Control | F12: Xbar-R and I-MR charts p and c charts | G12: baseline
A13: CT-DIV | B13: Divide and conquer | C13: Split the problem, solve the parts, combine the answers. | D13: Half-split troubleshooting and component search split a failing system in two each step. | E13: Analyze | F13: Half-split / component search | G13: baseline
... A28: CT-MEMO | B28: Memoization / caching | C28: Store a computed result so it is reused, not recomputed. | D28: Lessons-learned logs and the failure frequency chart reuse past root causes. | E28: Control | F28: Sustained capability and hand-off | G28: baseline

Sheet Statistics
A1: Statistics: Moore, McCabe & Craig, Introduction to the Practice of Statistics
A2: ID | B2: Method | C2: Use when | D2: Assumptions (check them) | E2: Formula | F2: Decision rule | G2: IPS chapter*
A3: ST-DESC | B3: Descriptive statistics | C3: Summarize a distribution. | D3: None. | E3: mean, s = sqrt(sum (x - xbar)^2 / (n - 1)); five-number summary; outlier if beyond Q1 - 1.5 IQR or Q3 + 1.5 IQR. | F3: Describe shape, center, spread, outliers before any test. | G3: 1-2
A4: ST-NORM | B4: Normal distribution and z | C4: Probabilities and percentiles for normal data. | D4: Data approximately normal (check plot). | E4: z = (x - mu) / sigma. | F4: Use the normal table or NORM.S.DIST(z, TRUE). | G4: 1
A5: ST-SAMP | B5: Sampling distributions and CLT | C5: Know how a statistic varies from sample to sample. | D5: Random sample; n large enough for CLT. | E5: SD(xbar) = sigma / sqrt(n). | F5: Larger n narrows the sampling distribution by sqrt(n). | G5: 3, 5
A6: ST-T1 | B6: One-sample t (CI and test) | C6: Estimate or test one mean. | D6: Random sample. IPS guideline: n < 15 needs near-normal data; n >= 15 unless outliers or strong skew; n >= 40 is fine even if skewed. | E6: xbar +/- t* s / sqrt(n), df = n - 1. t = (xbar - mu0) / (s / sqrt(n)). | F6: Reject H0 when p < alpha. | G6: 7
A7: ST-TP | B7: Paired t | C7: Before/after on the same units. | D7: Differences approximately normal. | E7: t = dbar / (s_d / sqrt(n)), df = n - 1. | F7: Reject H0 when p < alpha. | G7: 7
A8: ST-T2 | B8: Two-sample t (Welch) | C8: Compare two independent means. | D8: Independent random samples. IPS guideline on n1 + n2: < 15 near-normal; >= 15 unless outliers or strong skew; >= 40 even if skewed. | E8: t = (xbar1 - xbar2) / sqrt(s1^2/n1 + s2^2/n2); df by Welch or conservative min(n1, n2) - 1. | F8: Reject H0 when p < alpha. | G8: 7
A9: ST-PROP | B9: Inference for proportions | C9: Estimate or compare defect rates. | D9: CI: successes and failures >= 10 (each sample). Test: n p0 and n(1 - p0) >= 10; two-sample test >= 5 each. Plus-four: n >= 10 (one sample) or >= 5 each (two). | E9: phat +/- z* sqrt(phat(1 - phat)/n). Two-proportion z: pooled p in the test SE, unpooled SE in the CI. | F9: Reject H0 when p < alpha. | G9: 8
A10: ST-CHI | B10: Chi-square test for two-way tables | C10: Test association between two categorical variables. | D10: 2 x 2: all expected counts >= 5. Larger tables: average expected >= 5 and minimum >= 1 (IPS). Otherwise Fisher's exact. | E10: X^2 = sum (O - E)^2 / E, E = row total x column total / n, df = (r - 1)(c - 1). | F10: Reject independence when p < alpha. | G10: 9
A11: ST-REG | B11: Simple linear regression inference | C11: Test and estimate a straight-line relationship. | D11: Linearity, independence, normal residuals, equal variance (check residual plots). | E11: b1 = r sy / sx; t = b1 / SE(b1), df = n - 2. | F11: Slope significant when p < alpha. | G11: 10
A12: ST-MREG | B12: Multiple regression | C12: Model Y from several X. | D12: As simple regression; check multicollinearity. | E12: Overall F test; t test per coefficient; R^2 and adjusted R^2. | F12: Keep terms significant at alpha that make physical sense. | G12: 11
A13: ST-ANOVA1 | B13: One-way ANOVA | C13: Compare 3+ means. | D13: Independent samples, normal, equal SDs (largest/smallest s < 2). | E13: F = MSG / MSE. | F13: Reject equal means when p < alpha; follow with multiple comparisons (Tukey or Bonferroni). | G13: 12
... A20: ST-CAP | B20: Process capability | C20: Compare process spread to spec. | D20: Process in control; distribution known (often normal). | E20: Cp, Cpk, Pp, Ppk (see Six Sigma sheet). | F20: Compute only after control is shown. | G20: 17 (companion)
A22: * Likely chapter in recent editions. Verify against the owner's edition; the stats-book extraction replaces this sheet.

Sheet Decision Algorithms
A1: Decision algorithms: test selection, chart selection, project loop
A2: 1. Hypothesis test selection (check normality and equal variance first)
A3: Y (output) type | B3: X (input) type | C3: Case | D3: Normal-theory test | E3: Nonparametric / exact alternative
A4: Continuous | B4: None (vs target) | C4: 1 sample | D4: One-sample t (ST-T1) | E4: Wilcoxon signed rank (ST-NP)
A5: Continuous | B5: Categorical | C5: 2 paired | D5: Paired t (ST-TP) | E5: Wilcoxon signed rank (ST-NP)
A6: Continuous | B6: Categorical | C6: 2 independent | D6: Welch two-sample t (ST-T2) | E6: Wilcoxon rank sum / Mann-Whitney (ST-NP)
A7: Continuous | B7: Categorical | C7: 3+ groups | D7: One-way ANOVA (ST-ANOVA1) | E7: Kruskal-Wallis (ST-NP)
A8: Continuous | B8: Categorical | C8: 2 factors | D8: Two-way ANOVA (ST-ANOVA2) | E8: Friedman (one block factor), aligned rank transform, or permutation / bootstrap (ST-BOOT)
A9: Continuous | B9: Categorical | C9: Compare spread, 2+ groups | D9: Levene or Bonett (software); F test only if normal (IPS warns it is not robust) | E9: Permutation test on variances
A10: Continuous | B10: Continuous | C10: 1 X | D10: Simple regression (ST-REG) | E10: Spearman rank correlation
A11: Continuous | B11: Continuous | C11: 2+ X | D11: Multiple regression / DOE (ST-MREG) | E11: Bootstrap coefficients (ST-BOOT)
A12: Attribute (pass/fail) | B12: None (vs target) | C12: 1 proportion | D12: One-proportion z (ST-PROP) | E12: Exact binomial test
A13: Attribute (pass/fail) | B13: Categorical | C13: 2 groups | D13: Two-proportion z (ST-PROP) | E13: Fisher's exact test
A14: Attribute (pass/fail) | B14: Categorical | C14: 2 paired | D14: McNemar | E14: Exact binomial on discordant pairs
... A18: Attribute (pass/fail) | B18: Continuous | C18: 1+ X | D18: Logistic regression (ST-LOGIT) | E18: Exact logistic regression
A20: 2. Control chart selection
A21: Data type | B21: Subgroup / sample | C21: Chart | D21: Control limits | E21: Typical use
A22: Continuous | B22: n = 1 | C22: I-MR | D22: xbar +/- 2.66 MRbar; MR: UCL = 3.267 MRbar, LCL = 0 | E22: One reading per period; slow or costly measurements.
A23: Continuous | B23: 2 to 9 | C23: Xbar-R | D23: Xbarbar +/- A2 Rbar; R: D3 Rbar to D4 Rbar | E23: Small rational subgroups (most common).
A24: Continuous | B24: 10 or more | C24: Xbar-S | D24: Xbarbar +/- A3 sbar; S: B3 sbar to B4 sbar | E24: Large subgroups; s estimates spread better than R.
A25: Defectives (pass/fail) | B25: Constant n | C25: np | D25: n pbar +/- 3 sqrt(n pbar (1 - pbar)); LCL floors at 0 | E25: Count of defective units, fixed sample size.
A26: Defectives (pass/fail) | B26: Varying n | C26: p | D26: pbar +/- 3 sqrt(pbar (1 - pbar) / n_i); LCL floors at 0 | E26: Fraction defective; limits change with each n_i.
A27: Defects (counts) | B27: Constant area | C27: c | D27: cbar +/- 3 sqrt(cbar); LCL floors at 0 | E27: Defects per unit, same inspection area each time.
A28: Defects (counts) | B28: Varying area | C28: u | D28: ubar +/- 3 sqrt(ubar / n_i); LCL floors at 0 | E28: Defects per unit when inspection area varies.
A29: Defectives or defects | B29: Very large n, limits too tight | C29: Laney p' / u' | D29: p or u limits x sigma_Z | E29: Overdispersed attribute data.
A30: Continuous | B30: Any; detect shifts < 1.5 sigma | C30: EWMA or CUSUM | D30: Software (lambda, L or k, h) | E30: Small sustained shifts; complements a Shewhart chart.
A32: 2b. Control chart constants by subgroup size n
A33: n | B33: A2 | C33: D3 | D33: D4 | E33: A3 | F33: B3 | G33: B4 | H33: d2 | I33: c4
A34: 2 | B34: 1.88 | C34: 0 | D34: 3.267 | E34: 2.659 | F34: 0 | G34: 3.267 | H34: 1.128 | I34: 0.7979
A35: 3 | B35: 1.023 | C35: 0 | D35: 2.574 | E35: 1.954 | F35: 0 | G35: 2.568 | H35: 1.693 | I35: 0.8862
A36: 4 | B36: 0.729 | C36: 0 | D36: 2.282 | E36: 1.628 | F36: 0 | G36: 2.266 | H36: 2.059 | I36: 0.9213
A37: 5 | B37: 0.577 | C37: 0 | D37: 2.114 | E37: 1.427 | F37: 0 | G37: 2.089 | H37: 2.326 | I37: 0.94
A38: 6 | B38: 0.483 | C38: 0 | D38: 2.004 | E38: 1.287 | F38: 0.03 | G38: 1.97 | H38: 2.534 | I38: 0.9515
A39: 7 | B39: 0.419 | C39: 0.076 | D39: 1.924 | E39: 1.182 | F39: 0.118 | G39: 1.882 | H39: 2.704 | I39: 0.9594
A40: 8 | B40: 0.373 | C40: 0.136 | D40: 1.864 | E40: 1.099 | F40: 0.185 | G40: 1.815 | H40: 2.847 | I40: 0.965
A41: 9 | B41: 0.337 | C41: 0.184 | D41: 1.816 | E41: 1.032 | F41: 0.239 | G41: 1.761 | H41: 2.97 | I41: 0.9693
A42: 10 | B42: 0.308 | C42: 0.223 | D42: 1.777 | E42: 0.975 | F42: 0.284 | G42: 1.716 | H42: 3.078 | I42: 0.9727
A44: 3. Project loop with stop conditions and term limits
A45: Step | B45: Action | C45: Check | D45: If yes, go to | E45: If no, go to
A46: 1 | B46: Write the objective, metric, baseline, target, and done-when line. | C46: All five written? | D46: 2 | E46: Stop: ask the owner
...

Sheet Failure Log
A1: Failure log: one row per failure, every project, every run
A2: Date | B2: Project | C2: Agent | D2: Category | E2: What happened | F2: Root cause | G2: Fix / rule added | H2: Recurrence (Y/N)
A3: 2026-10-08 | B3: two-arm-digital-gantry | C3: Grok | D3: Absence treated as proof | E3: A 404 on a hardware repo was recorded as 'name never created'. | F3: Lookup failure read as a fact about the world. | G3: Rule B3: record 'not found by <method>'. | H3: Y
A4: 2026-10-08 | B4: two-arm-digital-gantry | C4: Grok | D4: Claimed work not done | E4: CAD was reported but no CAD file existed. | F4: No claim ledger; claims not tied to paths. | G4: Rule B3: every claim needs a file path. | H4: Y
A5: 2026-10-08 | B5: two-arm-digital-gantry | C5: Grok | D5: Unknown left in a table | E5: Motor table published with servo repo 'unknown' and no dimensions. | F5: Agent stopped at search instead of designing. | G5: Rule A7: source, design, or give search terms. | H5: Y
A6: 2026-10-08 | B6: two-arm-digital-gantry | C6: Grok | D6: Unreadable image or CAD view | E6: Image output was not readable; wasted owner time. | F6: No pagination check before reporting. | G6: Rule A8: open and check every image. | H6: Y
A7: 2026-10-08 | B7: two-arm-digital-gantry | C7: Grok | D7: Exit attempt / premature stop | E7: Agent kept trying to end before solving the problem. | F7: Vague completion criteria. | G7: Done-when line on every step; loop control. | H7: Y
A8: 2026-10-08 | B8: two-arm-digital-gantry | C8: Grok | D8: Objective drift | E8: Session did not deliver the original objective. | F8: No objective restatement before reporting. | G8: Rule B1 and B5: objective score. | H8: Y

Sheet Failure Pareto
A1: Failure Pareto: work the categories that reach 80% first
A2: Counts update from the Failure Log. Columns A and D are hidden helpers. Add a category in toolbox_data.py.
A3: Rank key | B3: Category | C3: Count | D3: Rank | E3: Category (sorted by count) | F3: Count | G3: Cumulative %
A4: =C4-ROW()/1000 | B4: Claimed work not done | C4: =COUNTIF('Failure Log'!$D$3:$D$502,B4) | D4: =RANK(A4,$A$4:$A$15) | E4: =INDEX($B$4:$B$15,MATCH(1,$D$4:$D$15,0)) | F4: =INDEX($C$4:$C$15,MATCH(1,$D$4:$D$15,0)) | G4: =IF(SUM($C$4:$C$15)=0,0,SUM($F$4:F4)/SUM($C$4:$C$15))
A5: =C5-ROW()/1000 | B5: Absence treated as proof | C5: =COUNTIF('Failure Log'!$D$3:$D$502,B5) | D5: =RANK(A5,$A$4:$A$15) | E5: =INDEX($B$4:$B$15,MATCH(2,$D$4:$D$15,0)) | F5: =INDEX($C$4:$C$15,MATCH(2,$D$4:$D$15,0)) | G5: =IF(SUM($C$4:$C$15)=0,0,SUM($F$4:F5)/SUM($C$4:$C$15))
A6: =C6-ROW()/1000 | B6: Unknown left in a table | C6: =COUNTIF('Failure Log'!$D$3:$D$502,B6) | D6: =RANK(A6,$A$4:$A$15) | E6: =INDEX($B$4:$B$15,MATCH(3,$D$4:$D$15,0)) | F6: =INDEX($C$4:$C$15,MATCH(3,$D$4:$D$15,0)) | G6: =IF(SUM($C$4:$C$15)=0,0,SUM($F$4:F6)/SUM($C$4:$C$15))
A7: =C7-ROW()/1000 | B7: Objective drift | C7: =COUNTIF('Failure Log'!$D$3:$D$502,B7) | D7: =RANK(A7,$A$4:$A$15) | E7: =INDEX($B$4:$B$15,MATCH(4,$D$4:$D$15,0)) | F7: =INDEX($C$4:$C$15,MATCH(4,$D$4:$D$15,0)) | G7: =IF(SUM($C$4:$C$15)=0,0,SUM($F$4:F7)/SUM($C$4:$C$15))
A8: =C8-ROW()/1000 | B8: Exit attempt / premature stop | C8: =COUNTIF('Failure Log'!$D$3:$D$502,B8) | D8: =RANK(A8,$A$4:$A$15) | E8: =INDEX($B$4:$B$15,MATCH(5,$D$4:$D$15,0)) | F8: =INDEX($C$4:$C$15,MATCH(5,$D$4:$D$15,0)) | G8: =IF(SUM($C$4:$C$15)=0,0,SUM($F$4:F8)/SUM($C$4:$C$15))
A9: =C9-ROW()/1000 | B9: Unreadable image or CAD view | C9: =COUNTIF('Failure Log'!$D$3:$D$502,B9) | D9: =RANK(A9,$A$4:$A$15) | E9: =INDEX($B$4:$B$15,MATCH(6,$D$4:$D$15,0)) | F9: =INDEX($C$4:$C$15,MATCH(6,$D$4:$D$15,0)) | G9: =IF(SUM($C$4:$C$15)=0,0,SUM($F$4:F9)/SUM($C$4:$C$15))
A10: =C10-ROW()/1000 | B10: Math or unit error | C10: =COUNTIF('Failure Log'!$D$3:$D$502,B10) | D10: =RANK(A10,$A$4:$A$15) | E10: =INDEX($B$4:$B$15,MATCH(7,$D$4:$D$15,0)) | F10: =INDEX($C$4:$C$15,MATCH(7,$D$4:$D$15,0)) | G10: =IF(SUM($C$4:$C$15)=0,0,SUM($F$4:F10)/SUM($C$4:$C$15))
A11: =C11-ROW()/1000 | B11: Unsourced value | C11: =COUNTIF('Failure Log'!$D$3:$D$502,B11) | D11: =RANK(A11,$A$4:$A$15) | E11: =INDEX($B$4:$B$15,MATCH(8,$D$4:$D$15,0)) | F11: =INDEX($C$4:$C$15,MATCH(8,$D$4:$D$15,0)) | G11: =IF(SUM($C$4:$C$15)=0,0,SUM($F$4:F11)/SUM($C$4:$C$15))
A12: =C12-ROW()/1000 | B12: Artifact not secured / not pushed | C12: =COUNTIF('Failure Log'!$D$3:$D$502,B12) | D12: =RANK(A12,$A$4:$A$15) | E12: =INDEX($B$4:$B$15,MATCH(9,$D$4:$D$15,0)) | F12: =INDEX($C$4:$C$15,MATCH(9,$D$4:$D$15,0)) | G12: =IF(SUM($C$4:$C$15)=0,0,SUM($F$4:F12)/SUM($C$4:$C$15))
A13: =C13-ROW()/1000 | B13: Wrong location / duplicate created | C13: =COUNTIF('Failure Log'!$D$3:$D$502,B13) | D13: =RANK(A13,$A$4:$A$15) | E13: =INDEX($B$4:$B$15,MATCH(10,$D$4:$D$15,0)) | F13: =INDEX($C$4:$C$15,MATCH(10,$D$4:$D$15,0)) | G13: =IF(SUM($C$4:$C$15)=0,0,SUM($F$4:F13)/SUM($C$4:$C$15))
A14: =C14-ROW()/1000 | B14: Skill or procedure skipped | C14: =COUNTIF('Failure Log'!$D$3:$D$502,B14) | D14: =RANK(A14,$A$4:$A$15) | E14: =INDEX($B$4:$B$15,MATCH(11,$D$4:$D$15,0)) | F14: =INDEX($C$4:$C$15,MATCH(11,$D$4:$D$15,0)) | G14: =IF(SUM($C$4:$C$15)=0,0,SUM($F$4:F14)/SUM($C$4:$C$15))
A15: =C15-ROW()/1000 | B15: Tool or environment failure | C15: =COUNTIF('Failure Log'!$D$3:$D$502,B15) | D15: =RANK(A15,$A$4:$A$15) | E15: =INDEX($B$4:$B$15,MATCH(12,$D$4:$D$15,0)) | F15: =INDEX($C$4:$C$15,MATCH(12,$D$4:$D$15,0)) | G15: =IF(SUM($C$4:$C$15)=0,0,SUM($F$4:F15)/SUM($C$4:$C$15))
B16: Uncategorized log rows (must read 0) | C16: =COUNTA('Failure Log'!$D$3:$D$502)-SUM($C$4:$C$15)

Sheet Sources
A1: Sources and extraction status
A2: Source | B2: Feeds sheet | C2: Status | D2: Notes / what is needed
A3: Six Sigma methodology (owner's Six Sigma books) | B3: Six Sigma, Crosswalk | C3: baseline | D3: Book titles and paths needed; run extract/ with --lexicon six_sigma.
A4: Moore, McCabe & Craig, Introduction to the Practice of Statistics | B4: Statistics | C4: baseline | D4: Chapter numbers match the 6th to 9th editions (Fable review); 10th edition believed unchanged, unverified. Chapters 14 to 17 are online companion chapters. Codex stats extraction will replace this sheet.
A5: Owner's engineering statistics text | B5: Statistics | C5: pending | D5: Title needed.
A6: Introduction to Computational Thinking (owner's copy) | B6: Computational Thinking | C6: baseline | D6: Book not in this container. Rows are the standard computational-thinking methods (Wing 2006 and common algorithm design). Run extract/ with --lexicon computational_thinking and replace.
A7: AIAG MSA (4th ed.), AIAG FMEA (4th ed.), AIAG-VDA FMEA (2019), AIAG SPC | B7: Six Sigma, Decision Algorithms | C7: baseline | D7: Thresholds for %GRR, ndc, attribute agreement, FMEA RPN and Action Priority; chart constants. The 1.5 shift, Cpk, %GRR and kappa bands are not from IPS.
A8: Owner failure reports, 2026-10-08 | B8: Failure Log, Failure Pareto | C8: owner-reported | D8: Seed rows from the Grok two-arm digital gantry session.
